[2022-08-19 00:25:16,850: ERROR/SpawnPoolWorker-4] Task api.tasks.parseBooksTask[6c3f2f13-4dff-4130-a08b-8c00d5d2a82e] raised unexpected: ConnectionError(ProtocolError('Connection abor
ted.', RemoteDisconnected('Remote end closed connection without response')))
Traceback (most recent call last):
  File "C:\Users\Константин\AppData\Local\Programs\Python\Python39\lib\site-packages\urllib3\connectionpool.py", line 699, in urlopen
    httplib_response = self._make_request(
  File "C:\Users\Константин\AppData\Local\Programs\Python\Python39\lib\site-packages\urllib3\connectionpool.py", line 445, in _make_request
    six.raise_from(e, None)
  File "<string>", line 3, in raise_from
  File "C:\Users\Константин\AppData\Local\Programs\Python\Python39\lib\site-packages\urllib3\connectionpool.py", line 440, in _make_request
    httplib_response = conn.getresponse()
  File "C:\Users\Константин\AppData\Local\Programs\Python\Python39\lib\http\client.py", line 1377, in getresponse
    response.begin()
  File "C:\Users\Константин\AppData\Local\Programs\Python\Python39\lib\http\client.py", line 320, in begin
    version, status, reason = self._read_status()
  File "C:\Users\Константин\AppData\Local\Programs\Python\Python39\lib\http\client.py", line 289, in _read_status
    raise RemoteDisconnected("Remote end closed connection without"
http.client.RemoteDisconnected: Remote end closed connection without response

During handling of the above exception, another exception occurred:

Traceback (most recent call last):
  File "C:\Users\Константин\AppData\Local\Programs\Python\Python39\lib\site-packages\requests\adapters.py", line 440, in send
    resp = conn.urlopen(
  File "C:\Users\Константин\AppData\Local\Programs\Python\Python39\lib\site-packages\urllib3\connectionpool.py", line 755, in urlopen
    retries = retries.increment(
  File "C:\Users\Константин\AppData\Local\Programs\Python\Python39\lib\site-packages\urllib3\util\retry.py", line 532, in increment
    raise six.reraise(type(error), error, _stacktrace)
  File "C:\Users\Константин\AppData\Local\Programs\Python\Python39\lib\site-packages\urllib3\packages\six.py", line 769, in reraise
    raise value.with_traceback(tb)
  File "C:\Users\Константин\AppData\Local\Programs\Python\Python39\lib\site-packages\urllib3\connectionpool.py", line 699, in urlopen
    httplib_response = self._make_request(
  File "C:\Users\Константин\AppData\Local\Programs\Python\Python39\lib\site-packages\urllib3\connectionpool.py", line 445, in _make_request
    six.raise_from(e, None)
  File "<string>", line 3, in raise_from
  File "C:\Users\Константин\AppData\Local\Programs\Python\Python39\lib\site-packages\urllib3\connectionpool.py", line 440, in _make_request
    httplib_response = conn.getresponse()
  File "C:\Users\Константин\AppData\Local\Programs\Python\Python39\lib\http\client.py", line 1377, in getresponse
    response.begin()
  File "C:\Users\Константин\AppData\Local\Programs\Python\Python39\lib\http\client.py", line 320, in begin
    version, status, reason = self._read_status()
  File "C:\Users\Константин\AppData\Local\Programs\Python\Python39\lib\http\client.py", line 289, in _read_status
    raise RemoteDisconnected("Remote end closed connection without"
urllib3.exceptions.ProtocolError: ('Connection aborted.', RemoteDisconnected('Remote end closed connection without response'))

During handling of the above exception, another exception occurred:

Traceback (most recent call last):
  File "C:\Users\Константин\AppData\Local\Programs\Python\Python39\lib\site-packages\celery\app\trace.py", line 451, in trace_task
    R = retval = fun(*args, **kwargs)
  File "C:\Users\Константин\AppData\Local\Programs\Python\Python39\lib\site-packages\celery\app\trace.py", line 734, in __protected_call__
    return self.run(*args, **kwargs)
  File "D:\Projects\BooksDownloader\backend\api\tasks.py", line 46, in parseBooksTask
    path, fileName = parseBook(bookUrl)
  File "D:\Projects\BooksDownloader\backend\api\BooksParsingTool\parser.py", line 13, in parseBook
    text = get_html_and_render(url, render=shouldRender)
  File "D:\Projects\BooksDownloader\backend\api\BooksParsingTool\services\tools.py", line 15, in get_html_and_render
    r = session.get(url, data=data)
  File "C:\Users\Константин\AppData\Local\Programs\Python\Python39\lib\site-packages\requests\sessions.py", line 542, in get
    return self.request('GET', url, **kwargs)
  File "C:\Users\Константин\AppData\Local\Programs\Python\Python39\lib\site-packages\requests\sessions.py", line 529, in request
    resp = self.send(prep, **send_kwargs)
  File "C:\Users\Константин\AppData\Local\Programs\Python\Python39\lib\site-packages\requests\sessions.py", line 645, in send
    r = adapter.send(request, **kwargs)
  File "C:\Users\Константин\AppData\Local\Programs\Python\Python39\lib\site-packages\requests\adapters.py", line 501, in send
    raise ConnectionError(err, request=request)
requests.exceptions.ConnectionError: ('Connection aborted.', RemoteDisconnected('Remote end closed connection without response'))

